Workbook
Name _Hlk210070090: 'E-EM-RIM-CTb'!$A$3

Sheet E-Resumen
A1: Proceso | B1: Rutinario (Si/No) | C1: Identificación | G1: Evaluación del riesgo | R1: Criterios para establecer controles
C2: Peligro | D2: Código | E2: Riesgo | F2: Clasificación | G2: Nivel de Deficiencia (ND) | H2: Interpretación del Nivel de Deficiencia,(ND) | I2: Nivel de Exposición (NE) | J2: Interpretación del Nivel de Exposición (NE) | K2: Nivel de Probabilidad (NP) [ND X NE] | L2: Interpretación del Nivel de Probabilidad (NP) | M2: Nivel de Consecuencia (NC) | N2: Interpretación del Nivel de Consecuencia (NC) | O2: Nivel de Riesgo (NR) | P2: Nivel de Intervención (NI) | Q2: Interpretación del NR | R2: Peor consecuencia | S2: Existencia Requisito Legal Específico Asociado (Si/No) | U2: I-Resumen'!A1
A3: Obras preliminares | B3: Si | C3: =IF(D3="","",IF(D3="010-E","Trabajo en altura/ zonas con desnivel",IF(D3="020-E","Superficies irregulares u obstruidas",IF(D3="030-E","Estructuras inestables/ espacios confinados",IF(D3="040-E","Desprendimiento de objetos",IF(D3="090-E","Manipulación de máquinas/ herramientas",IF(D3="100-E","Operaciones de conformado",IF(D3="110-E","Objetos fijos o móviles",IF(D3="250a-E","Situaciones fortuitas",IF(D3="230-E","Colisión/ impacto vehicular",IF(D3="250b-E","Situaciones fortuitas",IF(D3="160-E","Energía eléctrica",IF(D3="150a-E","Fuentes de calor",IF(D3="150b-E","Fuentes de calor",IF(D3="150c-E","Fuentes de calor",IF(D3="570","Condiciones inadecuadas",IF(D3="120-I","Maquinaria pesada",IF(D3="330","Niveles sonoros",IF(D3="340","Movimientos oscilatorios",IF(D3="360","Fuentes emisoras de energía",IF(D3="170","Sustancias químicas",IF(D3="380","Niveles lumínicos",IF(D3="010-I","Trabajo en altura/ zonas con desnivel",IF(D3="020-I","Superficies irregulares u obstruidas",IF(D3="030-I","Estructuras inestables/ espacios confinados",IF(D3="040-I","Desprendimiento de objetos",IF(D3="090-I","Manipulación de máquinas/ herramientas",IF(D3="100-I","Operaciones de conformado",IF(D3="110-I","Objetos fijos o móviles",IF(D3="250a-I","Situaciones fortuitas",IF(D3="230-I","Colisión/ impacto vehicular",IF(D3="250b-I","Situaciones fortuitas",IF(D3="160-I","Energía eléctrica",IF(D3="390","Atmósferas contaminadas",IF(D3="130","Posturas forzadas/ manipulación manual de cargas"))))))))))))))))))))))))))))))))))) -> Niveles sonoros | D3: 330 | E3: =IF(D3="","",IF(D3="010-E","Caída de personas a distinto nivel",IF(D3="020-E","Caída de personas al mismo nivel",IF(D3="030-E","Caída de objetos por desplome",IF(D3="040-E","Caída de objetos en manipulación",IF(D3="090-E","Golpes/cortes por objetos o herramientas",IF(D3="110-E","Atrapamiento por o entre objetos",IF(D3="100-E","Proyección de fragmentos o partículas",IF(D3="230-E","Atropellos o golpes con vehículos",IF(D3="250a-E","Otros riesgos de accidente a) inherentes a la manipulación de herramientas eléctricas",IF(D3="250b-E","Otros riesgos de accidente b) Inherentes a la manipulación de herramientas manuales",IF(D3="160-E","Contactos Eléctricos",IF(D3="150a-E","Contactos térmicos a) inherentes al trabajador",IF(D3="150b-E","Contactos térmicos b) inherentes a la manipulación de elementos estructurales",IF(D3="150c-E","Contactos térmicos c) inherentes al proceso de soldadura",IF(D3="570","Organización del trabajo incorrecta",IF(D3="120-I","Atrapamiento por vuelco de máquinas",IF(D3="","",IF(D3="010-I","Caída de personas a distinto nivel",IF(D3="020-I","Caída de personas al mismo nivel",IF(D3="030-I","Caída de objetos por desplome",IF(D3="040-I","Caída de objetos en manipulación",IF(D3="090-I","Golpes/cortes por objetos o herramientas",IF(D3="110-I","Atrapamiento por o entre objetos",IF(D3="100-I","Proyección de fragmentos o partículas",IF(D3="230-I","Atropellos o golpes con vehículos",IF(D3="250a-I","Otros riesgos de accidente a) inherentes a la manipulación de herramientas eléctricas",IF(D3="250b-I","Otros riesgos de accidente b) Inherentes a la manipulación de herramientas manuales",IF(D3="390","Otra exposición a) asfixia o intoxicación",IF(D3="160-I","Contactos Eléctricos",IF(D3="570","Organización del trabajo incorrecta",IF(D3="120-I","Atrapamiento por vuelco de máquinas",IF(D3="330","Ruido",IF(D3="340","Vibración",IF(D3="360","Radiaciones ionizantes",IF(D3="170","Exposición a sustancias nocivas",IF(D3="130","Sobreesfuerzos",IF(D3="380","Iluminación",IF(D3="330","Ruido",IF(D3="340","Vibración",IF(D3="360","Radiaciones ionizantes",IF(D3="170","Exposición a sustancias nocivas",IF(D3="130","Sobreesfuerzos",IF(D3="380","Iluminación")))))))))))))))))))))))))))))))))))))))))))) -> Ruido | F3: =IF(D3="","",IF(D3="010-E","Riesgo de seguridad (Riesgo Mecánico)",IF(D3="020-E","Riesgo de seguridad (Riesgo Mecánico)",IF(D3="030-E","Riesgo de seguridad (Riesgo Mecánico)",IF(D3="040-E","Riesgo de seguridad (Riesgo Mecánico)",IF(D3="090-E","Riesgo de seguridad (Riesgo Mecánico)",IF(D3="110-E","Riesgo de seguridad (Riesgo Mecánico)",IF(D3="100-E","Riesgo de seguridad (Riesgo Mecánico)",IF(D3="230-E","Riesgo de seguridad (Riesgo Mecánico)",IF(D3="250a-E","Riesgo de seguridad (Riesgo Mecánico)",IF(D3="250b-E","Riesgo de seguridad (Riesgo Mecánico)",IF(D3="160-E","Riesgo de seguridad (Riesgo Eléctrico)",IF(D3="150a-E","Riesgo de seguridad (Riesgo Industrial Mayor)",IF(D3="150b-E","Riesgo de seguridad (Riesgo Industrial Mayor)",IF(D3="150c-E","Riesgo de seguridad (Riesgo Industrial Mayor)",IF(D3="570","Riesgo de seguridad (Riesgo Locativo)",IF(D3="120-I","Riesgo Mecánico",IF(D3="330","Riesgo Físico",IF(D3="340","Riesgo Físico",IF(D3="360","Riesgo Físico",IF(D3="170","Riesgo Químico",IF(D3="130","Riesgo Ergonómico",IF(D3="380","Riesgo Físico",IF(D3="010-I","Riesgo de seguridad (Riesgo Mecánico)",IF(D3="020-I","Riesgo de seguridad (Riesgo Mecánico)",IF(D3="030-I","Riesgo de seguridad (Riesgo Mecánico)",IF(D3="040-I","Riesgo de seguridad (Riesgo Mecánico)",IF(D3="090-I","Riesgo de seguridad (Riesgo Mecánico)",IF(D3="110-I","Riesgo de seguridad (Riesgo Mecánico)",IF(D3="100-I","Riesgo de seguridad (Riesgo Mecánico)",IF(D3="230-I","Riesgo de seguridad (Riesgo Mecánico)",IF(D3="250a-I","Riesgo de seguridad (Riesgo Mecánico)",IF(D3="250b-I","Riesgo de seguridad (Riesgo Mecánico)",IF(D3="160-I","Riesgo de seguridad (Riesgo Eléctrico)",IF(D3="590","Riesgo de seguridad (Riesgo Mecánico)"))))))))))))))))))))))))))))))))))) -> Riesgo Físico | G3: ='E-OP-RC-RF-R'!I13 -> 10 | H3: =IF(G3="","",IF(AND(G3<=10,G3>6),"MD",IF(AND(G3<=6,G3>2),"D",IF(AND(G3<=2,G3>0),"M",IF(G3=0,"B"))))) -> MD | I3: 3 | J3: =IF(I3=4,"EC",IF(I3=3,"EF",IF(I3=2,"EO",IF(I3=1,"EE","")))) -> EF | K3: =IF(I3="","",G3*I3) -> 30 | L3: =IF(K3="","",IF(K3>=24,"MA",IF(AND(K3<24,K3>8),"A",IF(AND(K3<=8,K3>4),"M",IF(AND(K3<=4,K3>=0),"B"))))) -> MA | M3: 25 | N3: =IF(M3="","",IF(M3=100,"M",IF(M3=60,"MG",IF(M3=25,"G",IF(M3=10,"L",""))))) -> G | O3: =IF(M3="","",ROUND(M3*K3,0)) -> 750 | P3: =IF(O3="","",IF(O3="","",IF(AND(O3<=4000,O3>500),"I",IF(AND(O3<=500,O3>120),"II",IF(AND(O3<=120,O3>20),"III",IF(O3<=20,"IV")))))) -> I | Q3: =IF(P3="","",IF(P3="I","Situación Crítica. Corrección urgente.",IF(P3="II","Corregir y adoptar medidas de control.",IF(P3="III","Mejorar si es posible. Sería conveniente justificar la intervención y su rentabilidad.",IF(P3="IV","No intervenir, salvo que un análisis más preciso lo justifique."))))) -> Situación Crítica. Corrección urgente. | R3: =IF(M3=10,"Pequeñas lesiones que no requieren hospitalización.",IF(M3=25,"Lesiones con incapacidad laboral transitoria (I. L. T.).",IF(M3=60,"Lesiones graves que pueden ser irreparables.",IF(M3=100,"1 muerto o más.")))) -> Lesiones con incapacidad laboral transitoria (I. L. T.). | S3: Si
B4: Si | C4: =IF(D4="","",IF(D4="010-E","Trabajo en altura/ zonas con desnivel",IF(D4="020-E","Superficies irregulares u obstruidas",IF(D4="030-E","Estructuras inestables/ espacios confinados",IF(D4="040-E","Desprendimiento de objetos",IF(D4="090-E","Manipulación de máquinas/ herramientas",IF(D4="100-E","Operaciones de conformado",IF(D4="110-E","Objetos fijos o móviles",IF(D4="250a-E","Situaciones fortuitas",IF(D4="230-E","Colisión/ impacto vehicular",IF(D4="250b-E","Situaciones fortuitas",IF(D4="160-E","Energía eléctrica",IF(D4="150a-E","Fuentes de calor",IF(D4="150b-E","Fuentes de calor",IF(D4="150c-E","Fuentes de calor",IF(D4="570","Condiciones inadecuadas",IF(D4="120-I","Maquinaria pesada",IF(D4="330","Niveles sonoros",IF(D4="340","Movimientos oscilatorios",IF(D4="360","Fuentes emisoras de energía",IF(D4="170","Sustancias químicas",IF(D4="380","Niveles lumínicos",IF(D4="010-I","Trabajo en altura/ zonas con desnivel",IF(D4="020-I","Superficies irregulares u obstruidas",IF(D4="030-I","Estructuras inestables/ espacios confinados",IF(D4="040-I","Desprendimiento de objetos",IF(D4="090-I","Manipulación de máquinas/ herramientas",IF(D4="100-I","Operaciones de conformado",IF(D4="110-I","Objetos fijos o móviles",IF(D4="250a-I","Situaciones fortuitas",IF(D4="230-I","Colisión/ impacto vehicular",IF(D4="250b-I","Situaciones fortuitas",IF(D4="160-I","Energía eléctrica",IF(D4="390","Atmósferas contaminadas",IF(D4="130","Posturas forzadas/ manipulación manual de cargas"))))))))))))))))))))))))))))))))))) -> Niveles lumínicos | D4: 380 | E4: =IF(D4="","",IF(D4="010-E","Caída de personas a distinto nivel",IF(D4="020-E","Caída de personas al mismo nivel",IF(D4="030-E","Caída de objetos por desplome",IF(D4="040-E","Caída de objetos en manipulación",IF(D4="090-E","Golpes/cortes por objetos o herramientas",IF(D4="110-E","Atrapamiento por o entre objetos",IF(D4="100-E","Proyección de fragmentos o partículas",IF(D4="230-E","Atropellos o golpes con vehículos",IF(D4="250a-E","Otros riesgos de accidente a) inherentes a la manipulación de herramientas eléctricas",IF(D4="250b-E","Otros riesgos de accidente b) Inherentes a la manipulación de herramientas manuales",IF(D4="160-E","Contactos Eléctricos",IF(D4="150a-E","Contactos térmicos a) inherentes al trabajador",IF(D4="150b-E","Contactos térmicos b) inherentes a la manipulación de elementos estructurales",IF(D4="150c-E","Contactos térmicos c) inherentes al proceso de soldadura",IF(D4="570","Organización del trabajo incorrecta",IF(D4="120-I","Atrapamiento por vuelco de máquinas",IF(D4="","",IF(D4="010-I","Caída de personas a distinto nivel",IF(D4="020-I","Caída de personas al mismo nivel",IF(D4="030-I","Caída de objetos por desplome",IF(D4="040-I","Caída de objetos en manipulación",IF(D4="090-I","Golpes/cortes por objetos o herramientas",IF(D4="110-I","Atrapamiento por o entre objetos",IF(D4="100-I","Proyección de fragmentos o partículas",IF(D4="230-I","Atropellos o golpes con vehículos",IF(D4="250a-I","Otros riesgos de accidente a) inherentes a la manipulación de herramientas eléctricas",IF(D4="250b-I","Otros riesgos de accidente b) Inherentes a la manipulación de herramientas manuales",IF(D4="390","Otra exposición a) asfixia o intoxicación",IF(D4="160-I","Contactos Eléctricos",IF(D4="570","Organización del trabajo incorrecta",IF(D4="120-I","Atrapamiento por vuelco de máquinas",IF(D4="330","Ruido",IF(D4="340","Vibración",IF(D4="360","Radiaciones ionizantes",IF(D4="170","Exposición a sustancias nocivas",IF(D4="130","Sobreesfuerzos",IF(D4="380","Iluminación",IF(D4="330","Ruido",IF(D4="340","Vibración",IF(D4="360","Radiaciones ionizantes",IF(D4="170","Exposición a sustancias nocivas",IF(D4="130","Sobreesfuerzos",IF(D4="380","Iluminación")))))))))))))))))))))))))))))))))))))))))))) -> Iluminación | F4: =IF(D4="","",IF(D4="010-E","Riesgo de seguridad (Riesgo Mecánico)",IF(D4="020-E","Riesgo de seguridad (Riesgo Mecánico)",IF(D4="030-E","Riesgo de seguridad (Riesgo Mecánico)",IF(D4="040-E","Riesgo de seguridad (Riesgo Mecánico)",IF(D4="090-E","Riesgo de seguridad (Riesgo Mecánico)",IF(D4="110-E","Riesgo de seguridad (Riesgo Mecánico)",IF(D4="100-E","Riesgo de seguridad (Riesgo Mecánico)",IF(D4="230-E","Riesgo de seguridad (Riesgo Mecánico)",IF(D4="250a-E","Riesgo de seguridad (Riesgo Mecánico)",IF(D4="250b-E","Riesgo de seguridad (Riesgo Mecánico)",IF(D4="160-E","Riesgo de seguridad (Riesgo Eléctrico)",IF(D4="150a-E","Riesgo de seguridad (Riesgo Industrial Mayor)",IF(D4="150b-E","Riesgo de seguridad (Riesgo Industrial Mayor)",IF(D4="150c-E","Riesgo de seguridad (Riesgo Industrial Mayor)",IF(D4="570","Riesgo de seguridad (Riesgo Locativo)",IF(D4="120-I","Riesgo Mecánico",IF(D4="330","Riesgo Físico",IF(D4="340","Riesgo Físico",IF(D4="360","Riesgo Físico",IF(D4="170","Riesgo Químico",IF(D4="130","Riesgo Ergonómico",IF(D4="380","Riesgo Físico",IF(D4="010-I","Riesgo de seguridad (Riesgo Mecánico)",IF(D4="020-I","Riesgo de seguridad (Riesgo Mecánico)",IF(D4="030-I","Riesgo de seguridad (Riesgo Mecánico)",IF(D4="040-I","Riesgo de seguridad (Riesgo Mecánico)",IF(D4="090-I","Riesgo de seguridad (Riesgo Mecánico)",IF(D4="110-I","Riesgo de seguridad (Riesgo Mecánico)",IF(D4="100-I","Riesgo de seguridad (Riesgo Mecánico)",IF(D4="230-I","Riesgo de seguridad (Riesgo Mecánico)",IF(D4="250a-I","Riesgo de seguridad (Riesgo Mecánico)",IF(D4="250b-I","Riesgo de seguridad (Riesgo Mecánico)",IF(D4="160-I","Riesgo de seguridad (Riesgo Eléctrico)",IF(D4="590","Riesgo de seguridad (Riesgo Mecánico)"))))))))))))))))))))))))))))))))))) -> Riesgo Físico | G4: ='E-OP-RC-RF-I'!I12 -> 6.8421053 | H4: =IF(G4="","",IF(AND(G4<=10,G4>6),"MD",IF(AND(G4<=6,G4>2),"D",IF(AND(G4<=2,G4>0),"M",IF(G4=0,"B"))))) -> MD | I4: 1 | J4: =IF(I4=4,"EC",IF(I4=3,"EF",IF(I4=2,"EO",IF(I4=1,"EE","")))) -> EE | K4: =IF(I4="","",G4*I4) -> 6.8421053 | L4: =IF(K4="","",IF(K4>=24,"MA",IF(AND(K4<24,K4>8),"A",IF(AND(K4<=8,K4>4),"M",IF(AND(K4<=4,K4>=0),"B"))))) -> M | M4: 25 | N4: =IF(M4="","",IF(M4=100,"M",IF(M4=60,"MG",IF(M4=25,"G",IF(M4=10,"L",""))))) -> G | O4: =IF(M4="","",ROUND(M4*K4,0)) -> 171 | P4: =IF(O4="","",IF(O4="","",IF(AND(O4<=4000,O4>500),"I",IF(AND(O4<=500,O4>120),"II",IF(AND(O4<=120,O4>20),"III",IF(O4<=20,"IV")))))) -> II | Q4: =IF(P4="","",IF(P4="I","Situación Crítica. Corrección urgente.",IF(P4="II","Corregir y adoptar medidas de control.",IF(P4="III","Mejorar si es posible. Sería conveniente justificar la intervención y su rentabilidad.",IF(P4="IV","No intervenir, salvo que un análisis más preciso lo justifique."))))) -> Corregir y adoptar medidas de control. | R4: =IF(M4=10,"Pequeñas lesiones que no requieren hospitalización.",IF(M4=25,"Lesiones con incapacidad laboral transitoria (I. L. T.).",IF(M4=60,"Lesiones graves que pueden ser irreparables.",IF(M4=100,"1 muerto o más.")))) -> Lesiones con incapacidad laboral transitoria (I. L. T.). | S4: Si
B5: Si | C5: =IF(D5="","",IF(D5="010-E","Trabajo en altura/ zonas con desnivel",IF(D5="020-E","Superficies irregulares u obstruidas",IF(D5="030-E","Estructuras inestables/ espacios confinados",IF(D5="040-E","Desprendimiento de objetos",IF(D5="090-E","Manipulación de máquinas/ herramientas",IF(D5="100-E","Operaciones de conformado",IF(D5="110-E","Objetos fijos o móviles",IF(D5="250a-E","Situaciones fortuitas",IF(D5="230-E","Colisión/ impacto vehicular",IF(D5="250b-E","Situaciones fortuitas",IF(D5="160-E","Energía eléctrica",IF(D5="150a-E","Fuentes de calor",IF(D5="150b-E","Fuentes de calor",IF(D5="150c-E","Fuentes de calor",IF(D5="570","Condiciones inadecuadas",IF(D5="120-I","Maquinaria pesada",IF(D5="330","Niveles sonoros",IF(D5="340","Movimientos oscilatorios",IF(D5="360","Fuentes emisoras de energía",IF(D5="170","Sustancias químicas",IF(D5="380","Niveles lumínicos",IF(D5="010-I","Trabajo en altura/ zonas con desnivel",IF(D5="020-I","Superficies irregulares u obstruidas",IF(D5="030-I","Estructuras inestables/ espacios confinados",IF(D5="040-I","Desprendimiento de objetos",IF(D5="090-I","Manipulación de máquinas/ herramientas",IF(D5="100-I","Operaciones de conformado",IF(D5="110-I","Objetos fijos o móviles",IF(D5="250a-I","Situaciones fortuitas",IF(D5="230-I","Colisión/ impacto vehicular",IF(D5="250b-I","Situaciones fortuitas",IF(D5="160-I","Energía eléctrica",IF(D5="390","Atmósferas contaminadas",IF(D5="130","Posturas forzadas/ manipulación manual de cargas"))))))))))))))))))))))))))))))))))) -> Condiciones inadecuadas | D5: 570 | E5: =IF(D5="","",IF(D5="010-E","Caída de personas a distinto nivel",IF(D5="020-E","Caída de personas al mismo nivel",IF(D5="030-E","Caída de objetos por desplome",IF(D5="040-E","Caída de objetos en manipulación",IF(D5="090-E","Golpes/cortes por objetos o herramientas",IF(D5="110-E","Atrapamiento por o entre objetos",IF(D5="100-E","Proyección de fragmentos o partículas",IF(D5="230-E","Atropellos o golpes con vehículos",IF(D5="250a-E","Otros riesgos de accidente a) inherentes a la manipulación de herramientas eléctricas",IF(D5="250b-E","Otros riesgos de accidente b) Inherentes a la manipulación de herramientas manuales",IF(D5="160-E","Contactos Eléctricos",IF(D5="150a-E","Contactos térmicos a) inherentes al trabajador",IF(D5="150b-E","Contactos térmicos b) inherentes a la manipulación de elementos estructurales",IF(D5="150c-E","Contactos térmicos c) inherentes al proceso de soldadura",IF(D5="570","Organización del trabajo incorrecta",IF(D5="120-I","Atrapamiento por vuelco de máquinas",IF(D5="","",IF(D5="010-I","Caída de personas a distinto nivel",IF(D5="020-I","Caída de personas al mismo nivel",IF(D5="030-I","Caída de objetos por desplome",IF(D5="040-I","Caída de objetos en manipulación",IF(D5="090-I","Golpes/cortes por objetos o herramientas",IF(D5="110-I","Atrapamiento por o entre objetos",IF(D5="100-I","Proyección de fragmentos o partículas",IF(D5="230-I","Atropellos o golpes con vehículos",IF(D5="250a-I","Otros riesgos de accidente a) inherentes a la manipulación de herramientas eléctricas",IF(D5="250b-I","Otros riesgos de accidente b) Inherentes a la manipulación de herramientas manuales",IF(D5="390","Otra exposición a) asfixia o intoxicación",IF(D5="160-I","Contactos Eléctricos",IF(D5="570","Organización del trabajo incorrecta",IF(D5="120-I","Atrapamiento por vuelco de máquinas",IF(D5="330","Ruido",IF(D5="340","Vibración",IF(D5="360","Radiaciones ionizantes",IF(D5="170","Exposición a sustancias nocivas",IF(D5="130","Sobreesfuerzos",IF(D5="380","Iluminación",IF(D5="330","Ruido",IF(D5="340","Vibración",IF(D5="360","Radiaciones ionizantes",IF(D5="170","Exposición a sustancias nocivas",IF(D5="130","Sobreesfuerzos",IF(D5="380","Iluminación")))))))))))))))))))))))))))))))))))))))))))) -> Organización del trabajo incorrecta | F5: =IF(D5="","",IF(D5="010-E","Riesgo de seguridad (Riesgo Mecánico)",IF(D5="020-E","Riesgo de seguridad (Riesgo Mecánico)",IF(D5="030-E","Riesgo de seguridad (Riesgo Mecánico)",IF(D5="040-E","Riesgo de seguridad (Riesgo Mecánico)",IF(D5="090-E","Riesgo de seguridad (Riesgo Mecánico)",IF(D5="110-E","Riesgo de seguridad (Riesgo Mecánico)",IF(D5="100-E","Riesgo de seguridad (Riesgo Mecánico)",IF(D5="230-E","Riesgo de seguridad (Riesgo Mecánico)",IF(D5="250a-E","Riesgo de seguridad (Riesgo Mecánico)",IF(D5="250b-E","Riesgo de seguridad (Riesgo Mecánico)",IF(D5="160-E","Riesgo de seguridad (Riesgo Eléctrico)",IF(D5="150a-E","Riesgo de seguridad (Riesgo Industrial Mayor)",IF(D5="150b-E","Riesgo de seguridad (Riesgo Industrial Mayor)",IF(D5="150c-E","Riesgo de seguridad (Riesgo Industrial Mayor)",IF(D5="570","Riesgo de seguridad (Riesgo Locativo)",IF(D5="120-I","Riesgo Mecánico",IF(D5="330","Riesgo Físico",IF(D5="340","Riesgo Físico",IF(D5="360","Riesgo Físico",IF(D5="170","Riesgo Químico",IF(D5="130","Riesgo Ergonómico",IF(D5="380","Riesgo Físico",IF(D5="010-I","Riesgo de seguridad (Riesgo Mecánico)",IF(D5="020-I","Riesgo de seguridad (Riesgo Mecánico)",IF(D5="030-I","Riesgo de seguridad (Riesgo Mecánico)",IF(D5="040-I","Riesgo de seguridad (Riesgo Mecánico)",IF(D5="090-I","Riesgo de seguridad (Riesgo Mecánico)",IF(D5="110-I","Riesgo de seguridad (Riesgo Mecánico)",IF(D5="100-I","Riesgo de seguridad (Riesgo Mecánico)",IF(D5="230-I","Riesgo de seguridad (Riesgo Mecánico)",IF(D5="250a-I","Riesgo de seguridad (Riesgo Mecánico)",IF(D5="250b-I","Riesgo de seguridad (Riesgo Mecánico)",IF(D5="160-I","Riesgo de seguridad (Riesgo Eléctrico)",IF(D5="590","Riesgo de seguridad (Riesgo Mecánico)"))))))))))))))))))))))))))))))))))) -> Riesgo de seguridad (Riesgo Locativo) | G5: ='E-OP-RL-OI'!J14 -> 7.027027 | H5: =IF(G5="","",IF(AND(G5<=10,G5>6),"MD",IF(AND(G5<=6,G5>2),"D",IF(AND(G5<=2,G5>0),"M",IF(G5=0,"B"))))) -> MD | I5: 3 | J5: =IF(I5=4,"EC",IF(I5=3,"EF",IF(I5=2,"EO",IF(I5=1,"EE","")))) -> EF | K5: =IF(I5="","",G5*I5) -> 21.081081 | L5: =IF(K5="","",IF(K5>=24,"MA",IF(AND(K5<24,K5>8),"A",IF(AND(K5<=8,K5>4),"M",IF(AND(K5<=4,K5>=0),"B"))))) -> A | M5: 25 | N5: =IF(M5="","",IF(M5=100,"M",IF(M5=60,"MG",IF(M5=25,"G",IF(M5=10,"L",""))))) -> G | O5: =IF(M5="","",ROUND(M5*K5,0)) -> 527 | P5: =IF(O5="","",IF(O5="","",IF(AND(O5<=4000,O5>500),"I",IF(AND(O5<=500,O5>120),"II",IF(AND(O5<=120,O5>20),"III",IF(O5<=20,"IV")))))) -> I | Q5: =IF(P5="","",IF(P5="I","Situación Crítica. Corrección urgente.",IF(P5="II","Corregir y adoptar medidas de control.",IF(P5="III","Mejorar si es posible. Sería conveniente justificar la intervención y su rentabilidad.",IF(P5="IV","No intervenir, salvo que un análisis más preciso lo justifique."))))) -> Situación Crítica. Corrección urgente. | R5: =IF(M5=10,"Pequeñas lesiones que no requieren hospitalización.",IF(M5=25,"Lesiones con incapacidad laboral transitoria (I. L. T.).",IF(M5=60,"Lesiones graves que pueden ser irreparables.",IF(M5=100,"1 muerto o más.")))) -> Lesiones con incapacidad laboral transitoria (I. L. T.). | S5: Si
B6: Si | C6: =IF(D6="","",IF(D6="010-E","Trabajo en altura/ zonas con desnivel",IF(D6="020-E","Superficies irregulares u obstruidas",IF(D6="030-E","Estructuras inestables/ espacios confinados",IF(D6="040-E","Desprendimiento de objetos",IF(D6="090-E","Manipulación de máquinas/ herramientas",IF(D6="100-E","Operaciones de conformado",IF(D6="110-E","Objetos fijos o móviles",IF(D6="250a-E","Situaciones fortuitas",IF(D6="230-E","Colisión/ impacto vehicular",IF(D6="250b-E","Situaciones fortuitas",IF(D6="160-E","Energía eléctrica",IF(D6="150a-E","Fuentes de calor",IF(D6="150b-E","Fuentes de calor",IF(D6="150c-E","Fuentes de calor",IF(D6="570","Condiciones inadecuadas",IF(D6="120-I","Maquinaria pesada",IF(D6="330","Niveles sonoros",IF(D6="340","Movimientos oscilatorios",IF(D6="360","Fuentes emisoras de energía",IF(D6="170","Sustancias químicas",IF(D6="380","Niveles lumínicos",IF(D6="010-I","Trabajo en altura/ zonas con desnivel",IF(D6="020-I","Superficies irregulares u obstruidas",IF(D6="030-I","Estructuras inestables/ espacios confinados",IF(D6="040-I","Desprendimiento de objetos",IF(D6="090-I","Manipulación de máquinas/ herramientas",IF(D6="100-I","Operaciones de conformado",IF(D6="110-I","Objetos fijos o móviles",IF(D6="250a-I","Situaciones fortuitas",IF(D6="230-I","Colisión/ impacto vehicular",IF(D6="250b-I","Situaciones fortuitas",IF(D6="160-I","Energía eléctrica",IF(D6="390","Atmósferas contaminadas",IF(D6="130","Posturas forzadas/ manipulación manual de cargas"))))))))))))))))))))))))))))))))))) -> Superficies irregulares u obstruidas | D6: 020-E | E6: =IF(D6="","",IF(D6="010-E","Caída de personas a distinto nivel",IF(D6="020-E","Caída de personas al mismo nivel",IF(D6="030-E","Caída de objetos por desplome",IF(D6="040-E","Caída de objetos en manipulación",IF(D6="090-E","Golpes/cortes por objetos o herramientas",IF(D6="110-E","Atrapamiento por o entre objetos",IF(D6="100-E","Proyección de fragmentos o partículas",IF(D6="230-E","Atropellos o golpes con vehículos",IF(D6="250a-E","Otros riesgos de accidente a) inherentes a la manipulación de herramientas eléctricas",IF(D6="250b-E","Otros riesgos de accidente b) Inherentes a la manipulación de herramientas manuales",IF(D6="160-E","Contactos Eléctricos",IF(D6="150a-E","Contactos térmicos a) inherentes al trabajador",IF(D6="150b-E","Contactos térmicos b) inherentes a la manipulación de elementos estructurales",IF(D6="150c-E","Contactos térmicos c) inherentes al proceso de soldadura",IF(D6="570","Organización del trabajo incorrecta",IF(D6="120-I","Atrapamiento por vuelco de máquinas",IF(D6="","",IF(D6="010-I","Caída de personas a distinto nivel",IF(D6="020-I","Caída de personas al mismo nivel",IF(D6="030-I","Caída de objetos por desplome",IF(D6="040-I","Caída de objetos en manipulación",IF(D6="090-I","Golpes/cortes por objetos o herramientas",IF(D6="110-I","Atrapamiento por o entre objetos",IF(D6="100-I","Proyección de fragmentos o partículas",IF(D6="230-I","Atropellos o golpes con vehículos",IF(D6="250a-I","Otros riesgos de accidente a) inherentes a la manipulación de herramientas eléctricas",IF(D6="250b-I","Otros riesgos de accidente b) Inherentes a la manipulación de herramientas manuales",IF(D6="390","Otra exposición a) asfixia o intoxicación",IF(D6="160-I","Contactos Eléctricos",IF(D6="570","Organización del trabajo incorrecta",IF(D6="120-I","Atrapamiento por vuelco de máquinas",IF(D6="330","Ruido",IF(D6="340","Vibración",IF(D6="360","Radiaciones ionizantes",IF(D6="170","Exposición a sustancias nocivas",IF(D6="130","Sobreesfuerzos",IF(D6="380","Iluminación",IF(D6="330","Ruido",IF(D6="340","Vibración",IF(D6="360","Radiaciones ionizantes",IF(D6="170","Exposición a sustancias nocivas",IF(D6="130","Sobreesfuerzos",IF(D6="380","Iluminación")))))))))))))))))))))))))))))))))))))))))))) -> Caída de personas al mismo nivel | F6: =IF(D6="","",IF(D6="010-E","Riesgo de seguridad (Riesgo Mecánico)",IF(D6="020-E","Riesgo de seguridad (Riesgo Mecánico)",IF(D6="030-E","Riesgo de seguridad (Riesgo Mecánico)",IF(D6="040-E","Riesgo de seguridad (Riesgo Mecánico)",IF(D6="090-E","Riesgo de seguridad (Riesgo Mecánico)",IF(D6="110-E","Riesgo de seguridad (Riesgo Mecánico)",IF(D6="100-E","Riesgo de seguridad (Riesgo Mecánico)",IF(D6="230-E","Riesgo de seguridad (Riesgo Mecánico)",IF(D6="250a-E","Riesgo de seguridad (Riesgo Mecánico)",IF(D6="250b-E","Riesgo de seguridad (Riesgo Mecánico)",IF(D6="160-E","Riesgo de seguridad (Riesgo Eléctrico)",IF(D6="150a-E","Riesgo de seguridad (Riesgo Industrial Mayor)",IF(D6="150b-E","Riesgo de seguridad (Riesgo Industrial Mayor)",IF(D6="150c-E","Riesgo de seguridad (Riesgo Industrial Mayor)",IF(D6="570","Riesgo de seguridad (Riesgo Locativo)",IF(D6="120-I","Riesgo Mecánico",IF(D6="330","Riesgo Físico",IF(D6="340","Riesgo Físico",IF(D6="360","Riesgo Físico",IF(D6="170","Riesgo Químico",IF(D6="130","Riesgo Ergonómico",IF(D6="380","Riesgo Físico",IF(D6="010-I","Riesgo de seguridad (Riesgo Mecánico)",IF(D6="020-I","Riesgo de seguridad (Riesgo Mecánico)",IF(D6="030-I","Riesgo de seguridad (Riesgo Mecánico)",IF(D6="040-I","Riesgo de seguridad (Riesgo Mecánico)",IF(D6="090-I","Riesgo de seguridad (Riesgo Mecánico)",IF(D6="110-I","Riesgo de seguridad (Riesgo Mecánico)",IF(D6="100-I","Riesgo de seguridad (Riesgo Mecánico)",IF(D6="230-I","Riesgo de seguridad (Riesgo Mecánico)",IF(D6="250a-I","Riesgo de seguridad (Riesgo Mecánico)",IF(D6="250b-I","Riesgo de seguridad (Riesgo Mecánico)",IF(D6="160-I","Riesgo de seguridad (Riesgo Eléctrico)",IF(D6="590","Riesgo de seguridad (Riesgo Mecánico)"))))))))))))))))))))))))))))))))))) -> Riesgo de seguridad (Riesgo Mecánico) | G6: ='E-OP-RM-CMN'!J15 -> 5.7692308 | H6: =IF(G6="","",IF(AND(G6<=10,G6>6),"MD",IF(AND(G6<=6,G6>2),"D",IF(AND(G6<=2,G6>0),"M",IF(G6=0,"B"))))) -> D | I6: 3 | J6: =IF(I6=4,"EC",IF(I6=3,"EF",IF(I6=2,"EO",IF(I6=1,"EE","")))) -> EF | K6: =IF(I6="","",G6*I6) -> 17.307692 | L6: =IF(K6="","",IF(K6>=24,"MA",IF(AND(K6<24,K6>8),"A",IF(AND(K6<=8,K6>4),"M",IF(AND(K6<=4,K6>=0),"B"))))) -> A | M6: 25 | N6: =IF(M6="","",IF(M6=100,"M",IF(M6=60,"MG",IF(M6=25,"G",IF(M6=10,"L",""))))) -> G | O6: =IF(M6="","",ROUND(M6*K6,0)) -> 433 | P6: =IF(O6="","",IF(O6="","",IF(AND(O6<=4000,O6>500),"I",IF(AND(O6<=500,O6>120),"II",IF(AND(O6<=120,O6>20),"III",IF(O6<=20,"IV")))))) -> II | Q6: =IF(P6="","",IF(P6="I","Situación Crítica. Corrección urgente.",IF(P6="II","Corregir y adoptar medidas de control.",IF(P6="III","Mejorar si es posible. Sería conveniente justificar la intervención y su rentabilidad.",IF(P6="IV","No intervenir, salvo que un análisis más preciso lo justifique."))))) -> Corregir y adoptar medidas de control. | R6: =IF(M6=10,"Pequeñas lesiones que no requieren hospitalización.",IF(M6=25,"Lesiones con incapacidad laboral transitoria (I. L. T.).",IF(M6=60,"Lesiones graves que pueden ser irreparables.",IF(M6=100,"1 muerto o más.")))) -> Lesiones con incapacidad laboral transitoria (I. L. T.). | S6: Si
B7: Si | C7: =IF(D7="","",IF(D7="010-E","Trabajo en altura/ zonas con desnivel",IF(D7="020-E","Superficies irregulares u obstruidas",IF(D7="030-E","Estructuras inestables/ espacios confinados",IF(D7="040-E","Desprendimiento de objetos",IF(D7="090-E","Manipulación de máquinas/ herramientas",IF(D7="100-E","Operaciones de conformado",IF(D7="110-E","Objetos fijos o móviles",IF(D7="250a-E","Situaciones fortuitas",IF(D7="230-E","Colisión/ impacto vehicular",IF(D7="250b-E","Situaciones fortuitas",IF(D7="160-E","Energía eléctrica",IF(D7="150a-E","Fuentes de calor",IF(D7="150b-E","Fuentes de calor",IF(D7="150c-E","Fuentes de calor",IF(D7="570","Condiciones inadecuadas",IF(D7="120-I","Maquinaria pesada",IF(D7="330","Niveles sonoros",IF(D7="340","Movimientos oscilatorios",IF(D7="360","Fuentes emisoras de energía",IF(D7="170","Sustancias químicas",IF(D7="380","Niveles lumínicos",IF(D7="010-I","Trabajo en altura/ zonas con desnivel",IF(D7="020-I","Superficies irregulares u obstruidas",IF(D7="030-I","Estructuras inestables/ espacios confinados",IF(D7="040-I","Desprendimiento de objetos",IF(D7="090-I","Manipulación de máquinas/ herramientas",IF(D7="100-I","Operaciones de conformado",IF(D7="110-I","Objetos fijos o móviles",IF(D7="250a-I","Situaciones fortuitas",IF(D7="230-I","Colisión/ impacto vehicular",IF(D7="250b-I","Situaciones fortuitas",IF(D7="160-I","Energía eléctrica",IF(D7="390","Atmósferas contaminadas",IF(D7="130","Posturas forzadas/ manipulación manual de cargas"))))))))))))))))))))))))))))))))))) -> Desprendimiento de objetos | D7: 040-E | E7: =IF(D7="","",IF(D7="010-E","Caída de personas a distinto nivel",IF(D7="020-E","Caída de personas al mismo nivel",IF(D7="030-E","Caída de objetos por desplome",IF(D7="040-E","Caída de objetos en manipulación",IF(D7="090-E","Golpes/cortes por objetos o herramientas",IF(D7="110-E","Atrapamiento por o entre objetos",IF(D7="100-E","Proyección de fragmentos o partículas",IF(D7="230-E","Atropellos o golpes con vehículos",IF(D7="250a-E","Otros riesgos de accidente a) inherentes a la manipulación de herramientas eléctricas",IF(D7="250b-E","Otros riesgos de accidente b) Inherentes a la manipulación de herramientas manuales",IF(D7="160-E","Contactos Eléctricos",IF(D7="150a-E","Contactos térmicos a) inherentes al trabajador",IF(D7="150b-E","Contactos térmicos b) inherentes a la manipulación de elementos estructurales",IF(D7="150c-E","Contactos térmicos c) inherentes al proceso de soldadura",IF(D7="570","Organización del trabajo incorrecta",IF(D7="120-I","Atrapamiento por vuelco de máquinas",IF(D7="","",IF(D7="010-I","Caída de personas a distinto nivel",IF(D7="020-I","Caída de personas al mismo nivel",IF(D7="030-I","Caída de objetos por desplome",IF(D7="040-I","Caída de objetos en manipulación",IF(D7="090-I","Golpes/cortes por objetos o herramientas",IF(D7="110-I","Atrapamiento por o entre objetos",IF(D7="100-I","Proyección de fragmentos o partículas",IF(D7="230-I","Atropellos o golpes con vehículos",IF(D7="250a-I","Otros riesgos de accidente a) inherentes a la manipulación de herramientas eléctricas",IF(D7="250b-I","Otros riesgos de accidente b) Inherentes a la manipulación de herramientas manuales",IF(D7="390","Otra exposición a) asfixia o intoxicación",IF(D7="160-I","Contactos Eléctricos",IF(D7="570","Organización del trabajo incorrecta",IF(D7="120-I","Atrapamiento por vuelco de máquinas",IF(D7="330","Ruido",IF(D7="340","Vibración",IF(D7="360","Radiaciones ionizantes",IF(D7="170","Exposición a sustancias nocivas",IF(D7="130","Sobreesfuerzos",IF(D7="380","Iluminación",IF(D7="330","Ruido",IF(D7="340","Vibración",IF(D7="360","Radiaciones ionizantes",IF(D7="170","Exposición a sustancias nocivas",IF(D7="130","Sobreesfuerzos",IF(D7="380","Iluminación")))))))))))))))))))))))))))))))))))))))))))) -> Caída de objetos en manipulación | F7: =IF(D7="","",IF(D7="010-E","Riesgo de seguridad (Riesgo Mecánico)",IF(D7="020-E","Riesgo de seguridad (Riesgo Mecánico)",IF(D7="030-E","Riesgo de seguridad (Riesgo Mecánico)",IF(D7="040-E","Riesgo de seguridad (Riesgo Mecánico)",IF(D7="090-E","Riesgo de seguridad (Riesgo Mecánico)",IF(D7="110-E","Riesgo de seguridad (Riesgo Mecánico)",IF(D7="100-E","Riesgo de seguridad (Riesgo Mecánico)",IF(D7="230-E","Riesgo de seguridad (Riesgo Mecánico)",IF(D7="250a-E","Riesgo de seguridad (Riesgo Mecánico)",IF(D7="250b-E","Riesgo de seguridad (Riesgo Mecánico)",IF(D7="160-E","Riesgo de seguridad (Riesgo Eléctrico)",IF(D7="150a-E","Riesgo de seguridad (Riesgo Industrial Mayor)",IF(D7="150b-E","Riesgo de seguridad (Riesgo Industrial Mayor)",IF(D7="150c-E","Riesgo de seguridad (Riesgo Industrial Mayor)",IF(D7="570","Riesgo de seguridad (Riesgo Locativo)",IF(D7="120-I","Riesgo Mecánico",IF(D7="330","Riesgo Físico",IF(D7="340","Riesgo Físico",IF(D7="360","Riesgo Físico",IF(D7="170","Riesgo Químico",IF(D7="130","Riesgo Ergonómico",IF(D7="380","Riesgo Físico",IF(D7="010-I","Riesgo de seguridad (Riesgo Mecánico)",IF(D7="020-I","Riesgo de seguridad (Riesgo Mecánico)",IF(D7="030-I","Riesgo de seguridad (Riesgo Mecánico)",IF(D7="040-I","Riesgo de seguridad (Riesgo Mecánico)",IF(D7="090-I","Riesgo de seguridad (Riesgo Mecánico)",IF(D7="110-I","Riesgo de seguridad (Riesgo Mecánico)",IF(D7="100-I","Riesgo de seguridad (Riesgo Mecánico)",IF(D7="230-I","Riesgo de seguridad (Riesgo Mecánico)",IF(D7="250a-I","Riesgo de seguridad (Riesgo Mecánico)",IF(D7="250b-I","Riesgo de seguridad (Riesgo Mecánico)",IF(D7="160-I","Riesgo de seguridad (Riesgo Eléctrico)",IF(D7="590","Riesgo de seguridad (Riesgo Mecánico)"))))))))))))))))))))))))))))))))))) -> Riesgo de seguridad (Riesgo Mecánico) | G7: ='E-OP-RM-COM'!J17 -> 2.3333333 | H7: =IF(G7="","",IF(AND(G7<=10,G7>6),"MD",IF(AND(G7<=6,G7>2),"D",IF(AND(G7<=2,G7>0),"M",IF(G7=0,"B"))))) -> D | I7: 3 | J7: =IF(I7=4,"EC",IF(I7=3,"EF",IF(I7=2,"EO",IF(I7=1,"EE","")))) -> EF | K7: =IF(I7="","",G7*I7) -> 7 | L7: =IF(K7="","",IF(K7>=24,"MA",IF(AND(K7<24,K7>8),"A",IF(AND(K7<=8,K7>4),"M",IF(AND(K7<=4,K7>=0),"B"))))) -> M | M7: 25 | N7: =IF(M7="","",IF(M7=100,"M",IF(M7=60,"MG",IF(M7=25,"G",IF(M7=10,"L",""))))) -> G | O7: =IF(M7="","",ROUND(M7*K7,0)) -> 175 | P7: =IF(O7="","",IF(O7="","",IF(AND(O7<=4000,O7>500),"I",IF(AND(O7<=500,O7>120),"II",IF(AND(O7<=120,O7>20),"III",IF(O7<=20,"IV")))))) -> II | Q7: =IF(P7="","",IF(P7="I","Situación Crítica. Corrección urgente.",IF(P7="II","Corregir y adoptar medidas de control.",IF(P7="III","Mejorar si es posible. Sería conveniente justificar la intervención y su rentabilidad.",IF(P7="IV","No intervenir, salvo que un análisis más preciso lo justifique."))))) -> Corregir y adoptar medidas de control. | R7: =IF(M7=10,"Pequeñas lesiones que no requieren hospitalización.",IF(M7=25,"Lesiones con incapacidad laboral transitoria (I. L. T.).",IF(M7=60,"Lesiones graves que pueden ser irreparables.",IF(M7=100,"1 muerto o más.")))) -> Lesiones con incapacidad laboral transitoria (I. L. T.). | S7: Si
B8: Si | C8: =IF(D8="","",IF(D8="010-E","Trabajo en altura/ zonas con desnivel",IF(D8="020-E","Superficies irregulares u obstruidas",IF(D8="030-E","Estructuras inestables/ espacios confinados",IF(D8="040-E","Desprendimiento de objetos",IF(D8="090-E","Manipulación de máquinas/ herramientas",IF(D8="100-E","Operaciones de conformado",IF(D8="110-E","Objetos fijos o móviles",IF(D8="250a-E","Situaciones fortuitas",IF(D8="230-E","Colisión/ impacto vehicular",IF(D8="250b-E","Situaciones fortuitas",IF(D8="160-E","Energía eléctrica",IF(D8="150a-E","Fuentes de calor",IF(D8="150b-E","Fuentes de calor",IF(D8="150c-E","Fuentes de calor",IF(D8="570","Condiciones inadecuadas",IF(D8="120-I","Maquinaria pesada",IF(D8="330","Niveles sonoros",IF(D8="340","Movimientos oscilatorios",IF(D8="360","Fuentes emisoras de energía",IF(D8="170","Sustancias químicas",IF(D8="380","Niveles lumínicos",IF(D8="010-I","Trabajo en altura/ zonas con desnivel",IF(D8="020-I","Superficies irregulares u obstruidas",IF(D8="030-I","Estructuras inestables/ espacios confinados",IF(D8="040-I","Desprendimiento de objetos",IF(D8="090-I","Manipulación de máquinas/ herramientas",IF(D8="100-I","Operaciones de conformado",IF(D8="110-I","Objetos fijos o móviles",IF(D8="250a-I","Situaciones fortuitas",IF(D8="230-I","Colisión/ impacto vehicular",IF(D8="250b-I","Situaciones fortuitas",IF(D8="160-I","Energía eléctrica",IF(D8="390","Atmósferas contaminadas",IF(D8="130","Posturas forzadas/ manipulación manual de cargas"))))))))))))))))))))))))))))))))))) -> Manipulación de máquinas/ herramientas | D8: 090-E | E8: =IF(D8="","",IF(D8="010-E","Caída de personas a distinto nivel",IF(D8="020-E","Caída de personas al mismo nivel",IF(D8="030-E","Caída de objetos por desplome",IF(D8="040-E","Caída de objetos en manipulación",IF(D8="090-E","Golpes/cortes por objetos o herramientas",IF(D8="110-E","Atrapamiento por o entre objetos",IF(D8="100-E","Proyección de fragmentos o partículas",IF(D8="230-E","Atropellos o golpes con vehículos",IF(D8="250a-E","Otros riesgos de accidente a) inherentes a la manipulación de herramientas eléctricas",IF(D8="250b-E","Otros riesgos de accidente b) Inherentes a la manipulación de herramientas manuales",IF(D8="160-E","Contactos Eléctricos",IF(D8="150a-E","Contactos térmicos a) inherentes al trabajador",IF(D8="150b-E","Contactos térmicos b) inherentes a la manipulación de elementos estructurales",IF(D8="150c-E","Contactos térmicos c) inherentes al proceso de soldadura",IF(D8="570","Organización del trabajo incorrecta",IF(D8="120-I","Atrapamiento por vuelco de máquinas",IF(D8="","",IF(D8="010-I","Caída de personas a distinto nivel",IF(D8="020-I","Caída de personas al mismo nivel",IF(D8="030-I","Caída de objetos por desplome",IF(D8="040-I","Caída de objetos en manipulación",IF(D8="090-I","Golpes/cortes por objetos o herramientas",IF(D8="110-I","Atrapamiento por o entre objetos",IF(D8="100-I","Proyección de fragmentos o partículas",IF(D8="230-I","Atropellos o golpes con vehículos",IF(D8="250a-I","Otros riesgos de accidente a) inherentes a la manipulación de herramientas eléctricas",IF(D8="250b-I","Otros riesgos de accidente b) Inherentes a la manipulación de herramientas manuales",IF(D8="390","Otra exposición a) asfixia o intoxicación",IF(D8="160-I","Contactos Eléctricos",IF(D8="570","Organización del trabajo incorrecta",IF(D8="120-I","Atrapamiento por vuelco de máquinas",IF(D8="330","Ruido",IF(D8="340","Vibración",IF(D8="360","Radiaciones ionizantes",IF(D8="170","Exposición a sustancias nocivas",IF(D8="130","Sobreesfuerzos",IF(D8="380","Iluminación",IF(D8="330","Ruido",IF(D8="340","Vibración",IF(D8="360","Radiaciones ionizantes",IF(D8="170","Exposición a sustancias nocivas",IF(D8="130","Sobreesfuerzos",IF(D8="380","Iluminación")))))))))))))))))))))))))))))))))))))))))))) -> Golpes/cortes por objetos o herramientas | F8: =IF(D8="","",IF(D8="010-E","Riesgo de seguridad (Riesgo Mecánico)",IF(D8="020-E","Riesgo de seguridad (Riesgo Mecánico)",IF(D8="030-E","Riesgo de seguridad (Riesgo Mecánico)",IF(D8="040-E","Riesgo de seguridad (Riesgo Mecánico)",IF(D8="090-E","Riesgo de seguridad (Riesgo Mecánico)",IF(D8="110-E","Riesgo de seguridad (Riesgo Mecánico)",IF(D8="100-E","Riesgo de seguridad (Riesgo Mecánico)",IF(D8="230-E","Riesgo de seguridad (Riesgo Mecánico)",IF(D8="250a-E","Riesgo de seguridad (Riesgo Mecánico)",IF(D8="250b-E","Riesgo de seguridad (Riesgo Mecánico)",IF(D8="160-E","Riesgo de seguridad (Riesgo Eléctrico)",IF(D8="150a-E","Riesgo de seguridad (Riesgo Industrial Mayor)",IF(D8="150b-E","Riesgo de seguridad (Riesgo Industrial Mayor)",IF(D8="150c-E","Riesgo de seguridad (Riesgo Industrial Mayor)",IF(D8="570","Riesgo de seguridad (Riesgo Locativo)",IF(D8="120-I","Riesgo Mecánico",IF(D8="330","Riesgo Físico",IF(D8="340","Riesgo Físico",IF(D8="360","Riesgo Físico",IF(D8="170","Riesgo Químico",IF(D8="130","Riesgo Ergonómico",IF(D8="380","Riesgo Físico",IF(D8="010-I","Riesgo de seguridad (Riesgo Mecánico)",IF(D8="020-I","Riesgo de seguridad (Riesgo Mecánico)",IF(D8="030-I","Riesgo de seguridad (Riesgo Mecánico)",IF(D8="040-I","Riesgo de seguridad (Riesgo Mecánico)",IF(D8="090-I","Riesgo de seguridad (Riesgo Mecánico)",IF(D8="110-I","Riesgo de seguridad (Riesgo Mecánico)",IF(D8="100-I","Riesgo de seguridad (Riesgo Mecánico)",IF(D8="230-I","Riesgo de seguridad (Riesgo Mecánico)",IF(D8="250a-I","Riesgo de seguridad (Riesgo Mecánico)",IF(D8="250b-I","Riesgo de seguridad (Riesgo Mecánico)",IF(D8="160-I","Riesgo de seguridad (Riesgo Eléctrico)",IF(D8="590","Riesgo de seguridad (Riesgo Mecánico)"))))))))))))))))))))))))))))))))))) -> Riesgo de seguridad (Riesgo Mecánico) | G8: ='E-OP-RM-CGOH'!J17 -> 5.3571429 | H8: =IF(G8="","",IF(AND(G8<=10,G8>6),"MD",IF(AND(G8<=6,G8>2),"D",IF(AND(G8<=2,G8>0),"M",IF(G8=0,"B"))))) -> D | I8: 4 | J8: =IF(I8=4,"EC",IF(I8=3,"EF",IF(I8=2,"EO",IF(I8=1,"EE","")))) -> EC | K8: =IF(I8="","",G8*I8) -> 21.428571 | L8: =IF(K8="","",IF(K8>=24,"MA",IF(AND(K8<24,K8>8),"A",IF(AND(K8<=8,K8>4),"M",IF(AND(K8<=4,K8>=0),"B"))))) -> A | M8: 60 | N8: =IF(M8="","",IF(M8=100,"M",IF(M8=60,"MG",IF(M8=25,"G",IF(M8=10,"L",""))))) -> MG | O8: =IF(M8="","",ROUND(M8*K8,0)) -> 1286 | P8: =IF(O8="","",IF(O8="","",IF(AND(O8<=4000,O8>500),"I",IF(AND(O8<=500,O8>120),"II",IF(AND(O8<=120,O8>20),"III",IF(O8<=20,"IV")))))) -> I | Q8: =IF(P8="","",IF(P8="I","Situación Crítica. Corrección urgente.",IF(P8="II","Corregir y adoptar medidas de control.",IF(P8="III","Mejorar si es posible. Sería conveniente justificar la intervención y su rentabilidad.",IF(P8="IV","No intervenir, salvo que un análisis más preciso lo justifique."))))) -> Situación Crítica. Corrección urgente. | R8: =IF(M8=10,"Pequeñas lesiones que no requieren hospitalización.",IF(M8=25,"Lesiones con incapacidad laboral transitoria (I. L. T.).",IF(M8=60,"Lesiones graves que pueden ser irreparables.",IF(M8=100,"1 muerto o más.")))) -> Lesiones graves que pueden ser irreparables. | S8: Si
B9: Si | C9: =IF(D9="","",IF(D9="010-E","Trabajo en altura/ zonas con desnivel",IF(D9="020-E","Superficies irregulares u obstruidas",IF(D9="030-E","Estructuras inestables/ espacios confinados",IF(D9="040-E","Desprendimiento de objetos",IF(D9="090-E","Manipulación de máquinas/ herramientas",IF(D9="100-E","Operaciones de conformado",IF(D9="110-E","Objetos fijos o móviles",IF(D9="250a-E","Situaciones fortuitas",IF(D9="230-E","Colisión/ impacto vehicular",IF(D9="250b-E","Situaciones fortuitas",IF(D9="160-E","Energía eléctrica",IF(D9="150a-E","Fuentes de calor",IF(D9="150b-E","Fuentes de calor",IF(D9="150c-E","Fuentes de calor",IF(D9="570","Condiciones inadecuadas",IF(D9="120-I","Maquinaria pesada",IF(D9="330","Niveles sonoros",IF(D9="340","Movimientos oscilatorios",IF(D9="360","Fuentes emisoras de energía",IF(D9="170","Sustancias químicas",IF(D9="380","Niveles lumínicos",IF(D9="010-I","Trabajo en altura/ zonas con desnivel",IF(D9="020-I","Superficies irregulares u obstruidas",IF(D9="030-I","Estructuras inestables/ espacios confinados",IF(D9="040-I","Desprendimiento de objetos",IF(D9="090-I","Manipulación de máquinas/ herramientas",IF(D9="100-I","Operaciones de conformado",IF(D9="110-I","Objetos fijos o móviles",IF(D9="250a-I","Situaciones fortuitas",IF(D9="230-I","Colisión/ impacto vehicular",IF(D9="250b-I","Situaciones fortuitas",IF(D9="160-I","Energía eléctrica",IF(D9="390","Atmósferas contaminadas",IF(D9="130","Posturas forzadas/ manipulación manual de cargas"))))))))))))))))))))))))))))))))))) -> Operaciones de conformado | D9: 100-E | E9: =IF(D9="","",IF(D9="010-E","Caída de personas a distinto nivel",IF(D9="020-E","Caída de personas al mismo nivel",IF(D9="030-E","Caída de objetos por desplome",IF(D9="040-E","Caída de objetos en manipulación",IF(D9="090-E","Golpes/cortes por objetos o herramientas",IF(D9="110-E","Atrapamiento por o entre objetos",IF(D9="100-E","Proyección de fragmentos o partículas",IF(D9="230-E","Atropellos o golpes con vehículos",IF(D9="250a-E","Otros riesgos de accidente a) inherentes a la manipulación de herramientas eléctricas",IF(D9="250b-E","Otros riesgos de accidente b) Inherentes a la manipulación de herramientas manuales",IF(D9="160-E","Contactos Eléctricos",IF(D9="150a-E","Contactos térmicos a) inherentes al trabajador",IF(D9="150b-E","Contactos térmicos b) inherentes a la manipulación de elementos estructurales",IF(D9="150c-E","Contactos térmicos c) inherentes al proceso de soldadura",IF(D9="570","Organización del trabajo incorrecta",IF(D9="120-I","Atrapamiento por vuelco de máquinas",IF(D9="","",IF(D9="010-I","Caída de personas a distinto nivel",IF(D9="020-I","Caída de personas al mismo nivel",IF(D9="030-I","Caída de objetos por desplome",IF(D9="040-I","Caída de objetos en manipulación",IF(D9="090-I","Golpes/cortes por objetos o herramientas",IF(D9="110-I","Atrapamiento por o entre objetos",IF(D9="100-I","Proyección de fragmentos o partículas",IF(D9="230-I","Atropellos o golpes con vehículos",IF(D9="250a-I","Otros riesgos de accidente a) inherentes a la manipulación de herramientas eléctricas",IF(D9="250b-I","Otros riesgos de accidente b) Inherentes a la manipulación de herramientas manuales",IF(D9="390","Otra exposición a) asfixia o intoxicación",IF(D9="160-I","Contactos Eléctricos",IF(D9="570","Organización del trabajo incorrecta",IF(D9="120-I","Atrapamiento por vuelco de máquinas",IF(D9="330","Ruido",IF(D9="340","Vibración",IF(D9="360","Radiaciones ionizantes",IF(D9="170","Exposición a sustancias nocivas",IF(D9="130","Sobreesfuerzos",IF(D9="380","Iluminación",IF(D9="330","Ruido",IF(D9="340","Vibración",IF(D9="360","Radiaciones ionizantes",IF(D9="170","Exposición a sustancias nocivas",IF(D9="130","Sobreesfuerzos",IF(D9="380","Iluminación")))))))))))))))))))))))))))))))))))))))))))) -> Proyección de fragmentos o partículas | F9: =IF(D9="","",IF(D9="010-E","Riesgo de seguridad (Riesgo Mecánico)",IF(D9="020-E","Riesgo de seguridad (Riesgo Mecánico)",IF(D9="030-E","Riesgo de seguridad (Riesgo Mecánico)",IF(D9="040-E","Riesgo de seguridad (Riesgo Mecánico)",IF(D9="090-E","Riesgo de seguridad (Riesgo Mecánico)",IF(D9="110-E","Riesgo de seguridad (Riesgo Mecánico)",IF(D9="100-E","Riesgo de seguridad (Riesgo Mecánico)",IF(D9="230-E","Riesgo de seguridad (Riesgo Mecánico)",IF(D9="250a-E","Riesgo de seguridad (Riesgo Mecánico)",IF(D9="250b-E","Riesgo de seguridad (Riesgo Mecánico)",IF(D9="160-E","Riesgo de seguridad (Riesgo Eléctrico)",IF(D9="150a-E","Riesgo de seguridad (Riesgo Industrial Mayor)",IF(D9="150b-E","Riesgo de seguridad (Riesgo Industrial Mayor)",IF(D9="150c-E","Riesgo de seguridad (Riesgo Industrial Mayor)",IF(D9="570","Riesgo de seguridad (Riesgo Locativo)",IF(D9="120-I","Riesgo Mecánico",IF(D9="330","Riesgo Físico",IF(D9="340","Riesgo Físico",IF(D9="360","Riesgo Físico",IF(D9="170","Riesgo Químico",IF(D9="130","Riesgo Ergonómico",IF(D9="380","Riesgo Físico",IF(D9="010-I","Riesgo de seguridad (Riesgo Mecánico)",IF(D9="020-I","Riesgo de seguridad (Riesgo Mecánico)",IF(D9="030-I","Riesgo de seguridad (Riesgo Mecánico)",IF(D9="040-I","Riesgo de seguridad (Riesgo Mecánico)",IF(D9="090-I","Riesgo de seguridad (Riesgo Mecánico)",IF(D9="110-I","Riesgo de seguridad (Riesgo Mecánico)",IF(D9="100-I","Riesgo de seguridad (Riesgo Mecánico)",IF(D9="230-I","Riesgo de seguridad (Riesgo Mecánico)",IF(D9="250a-I","Riesgo de seguridad (Riesgo Mecánico)",IF(D9="250b-I","Riesgo de seguridad (Riesgo Mecánico)",IF(D9="160-I","Riesgo de seguridad (Riesgo Eléctrico)",IF(D9="590","Riesgo de seguridad (Riesgo Mecánico)"))))))))))))))))))))))))))))))))))) -> Riesgo de seguridad (Riesgo Mecánico) | G9: ='E-OP-RM-PFP'!J13 -> 8.75 | H9: =IF(G9="","",IF(AND(G9<=10,G9>6),"MD",IF(AND(G9<=6,G9>2),"D",IF(AND(G9<=2,G9>0),"M",IF(G9=0,"B"))))) -> MD | I9: 3 | J9: =IF(I9=4,"EC",IF(I9=3,"EF",IF(I9=2,"EO",IF(I9=1,"EE","")))) -> EF | K9: =IF(I9="","",G9*I9) -> 26.25 | L9: =IF(K9="","",IF(K9>=24,"MA",IF(AND(K9<24,K9>8),"A",IF(AND(K9<=8,K9>4),"M",IF(AND(K9<=4,K9>=0),"B"))))) -> MA | M9: 60 | N9: =IF(M9="","",IF(M9=100,"M",IF(M9=60,"MG",IF(M9=25,"G",IF(M9=10,"L",""))))) -> MG | O9: =IF(M9="","",ROUND(M9*K9,0)) -> 1575 | P9: =IF(O9="","",IF(O9="","",IF(AND(O9<=4000,O9>500),"I",IF(AND(O9<=500,O9>120),"II",IF(AND(O9<=120,O9>20),"III",IF(O9<=20,"IV")))))) -> I | Q9: =IF(P9="","",IF(P9="I","Situación Crítica. Corrección urgente.",IF(P9="II","Corregir y adoptar medidas de control.",IF(P9="III","Mejorar si es posible. Sería conveniente justificar la intervención y su rentabilidad.",IF(P9="IV","No intervenir, salvo que un análisis más preciso lo justifique."))))) -> Situación Crítica. Corrección urgente. | R9: =IF(M9=10,"Pequeñas lesiones que no requieren hospitalización.",IF(M9=25,"Lesiones con incapacidad laboral transitoria (I. L. T.).",IF(M9=60,"Lesiones graves que pueden ser irreparables.",IF(M9=100,"1 muerto o más.")))) -> Lesiones graves que pueden ser irreparables. | S9: Si
B10: Si | C10: =IF(D10="","",IF(D10="010-E","Trabajo en altura/ zonas con desnivel",IF(D10="020-E","Superficies irregulares u obstruidas",IF(D10="030-E","Estructuras inestables/ espacios confinados",IF(D10="040-E","Desprendimiento de objetos",IF(D10="090-E","Manipulación de máquinas/ herramientas",IF(D10="100-E","Operaciones de conformado",IF(D10="110-E","Objetos fijos o móviles",IF(D10="250a-E","Situaciones fortuitas",IF(D10="230-E","Colisión/ impacto vehicular",IF(D10="250b-E","Situaciones fortuitas",IF(D10="160-E","Energía eléctrica",IF(D10="150a-E","Fuentes de calor",IF(D10="150b-E","Fuentes de calor",IF(D10="150c-E","Fuentes de calor",IF(D10="570","Condiciones inadecuadas",IF(D10="120-I","Maquinaria pesada",IF(D10="330","Niveles sonoros",IF(D10="340","Movimientos oscilatorios",IF(D10="360","Fuentes emisoras de energía",IF(D10="170","Sustancias químicas",IF(D10="380","Niveles lumínicos",IF(D10="010-I","Trabajo en altura/ zonas con desnivel",IF(D10="020-I","Superficies irregulares u obstruidas",IF(D10="030-I","Estructuras inestables/ espacios confinados",IF(D10="040-I","Desprendimiento de objetos",IF(D10="090-I","Manipulación de máquinas/ herramientas",IF(D10="100-I","Operaciones de conformado",IF(D10="110-I","Objetos fijos o móviles",IF(D10="250a-I","Situaciones fortuitas",IF(D10="230-I","Colisión/ impacto vehicular",IF(D10="250b-I","Situaciones fortuitas",IF(D10="160-I","Energía eléctrica",IF(D10="390","Atmósferas contaminadas",IF(D10="130","Posturas forzadas/ manipulación manual de cargas"))))))))))))))))))))))))))))))))))) -> Objetos fijos o móviles | D10: 110-E | E10: =IF(D10="","",IF(D10="010-E","Caída de personas a distinto nivel",IF(D10="020-E","Caída de personas al mismo nivel",IF(D10="030-E","Caída de objetos por desplome",IF(D10="040-E","Caída de objetos en manipulación",IF(D10="090-E","Golpes/cortes por objetos o herramientas",IF(D10="110-E","Atrapamiento por o entre objetos",IF(D10="100-E","Proyección de fragmentos o partículas",IF(D10="230-E","Atropellos o golpes con vehículos",IF(D10="250a-E","Otros riesgos de accidente a) inherentes a la manipulación de herramientas eléctricas",IF(D10="250b-E","Otros riesgos de accidente b) Inherentes a la manipulación de herramientas manuales",IF(D10="160-E","Contactos Eléctricos",IF(D10="150a-E","Contactos térmicos a) inherentes al trabajador",IF(D10="150b-E","Contactos térmicos b) inherentes a la manipulación de elementos estructurales",IF(D10="150c-E","Contactos térmicos c) inherentes al proceso de soldadura",IF(D10="570","Organización del trabajo incorrecta",IF(D10="120-I","Atrapamiento por vuelco de máquinas",IF(D10="","",IF(D10="010-I","Caída de personas a distinto nivel",IF(D10="020-I","Caída de personas al mismo nivel",IF(D10="030-I","Caída de objetos por desplome",IF(D10="040-I","Caída de objetos en manipulación",IF(D10="090-I","Golpes/cortes por objetos o herramientas",IF(D10="110-I","Atrapamiento por o entre objetos",IF(D10="100-I","Proyección de fragmentos o partículas",IF(D10="230-I","Atropellos o golpes con vehículos",IF(D10="250a-I","Otros riesgos de accidente a) inherentes a la manipulación de herramientas eléctricas",IF(D10="250b-I","Otros riesgos de accidente b) Inherentes a la manipulación de herramientas manuales",IF(D10="390","Otra exposición a) asfixia o intoxicación",IF(D10="160-I","Contactos Eléctricos",IF(D10="570","Organización del trabajo incorrecta",IF(D10="120-I","Atrapamiento por vuelco de máquinas",IF(D10="330","Ruido",IF(D10="340","Vibración",IF(D10="360","Radiaciones ionizantes",IF(D10="170","Exposición a sustancias nocivas",IF(D10="130","Sobreesfuerzos",IF(D10="380","Iluminación",IF(D10="330","Ruido",IF(D10="340","Vibración",IF(D10="360","Radiaciones ionizantes",IF(D10="170","Exposición a sustancias nocivas",IF(D10="130","Sobreesfuerzos",IF(D10="380","Iluminación")))))))))))))))))))))))))))))))))))))))))))) -> Atrapamiento por o entre objetos | F10: =IF(D10="","",IF(D10="010-E","Riesgo de seguridad (Riesgo Mecánico)",IF(D10="020-E","Riesgo de seguridad (Riesgo Mecánico)",IF(D10="030-E","Riesgo de seguridad (Riesgo Mecánico)",IF(D10="040-E","Riesgo de seguridad (Riesgo Mecánico)",IF(D10="090-E","Riesgo de seguridad (Riesgo Mecánico)",IF(D10="110-E","Riesgo de seguridad (Riesgo Mecánico)",IF(D10="100-E","Riesgo de seguridad (Riesgo Mecánico)",IF(D10="230-E","Riesgo de seguridad (Riesgo Mecánico)",IF(D10="250a-E","Riesgo de seguridad (Riesgo Mecánico)",IF(D10="250b-E","Riesgo de seguridad (Riesgo Mecánico)",IF(D10="160-E","Riesgo de seguridad (Riesgo Eléctrico)",IF(D10="150a-E","Riesgo de seguridad (Riesgo Industrial Mayor)",IF(D10="150b-E","Riesgo de seguridad (Riesgo Industrial Mayor)",IF(D10="150c-E","Riesgo de seguridad (Riesgo Industrial Mayor)",IF(D10="570","Riesgo de seguridad (Riesgo Locativo)",IF(D10="120-I","Riesgo Mecánico",IF(D10="330","Riesgo Físico",IF(D10="340","Riesgo Físico",IF(D10="360","Riesgo Físico",IF(D10="170","Riesgo Químico",IF(D10="130","Riesgo Ergonómico",IF(D10="380","Riesgo Físico",IF(D10="010-I","Riesgo de seguridad (Riesgo Mecánico)",IF(D10="020-I","Riesgo de seguridad (Riesgo Mecánico)",IF(D10="030-I","Riesgo de seguridad (Riesgo Mecánico)",IF(D10="040-I","Riesgo de seguridad (Riesgo Mecánico)",IF(D10="090-I","Riesgo de seguridad (Riesgo Mecánico)",IF(D10="110-I","Riesgo de seguridad (Riesgo Mecánico)",IF(D10="100-I","Riesgo de seguridad (Riesgo Mecánico)",IF(D10="230-I","Riesgo de seguridad (Riesgo Mecánico)",IF(D10="250a-I","Riesgo de seguridad (Riesgo Mecánico)",IF(D10="250b-I","Riesgo de seguridad (Riesgo Mecánico)",IF(D10="160-I","Riesgo de seguridad (Riesgo Eléctrico)",IF(D10="590","Riesgo de seguridad (Riesgo Mecánico)"))))))))))))))))))))))))))))))))))) -> Riesgo de seguridad (Riesgo Mecánico) | G10: ='E-OP-RM-APEO'!J17 -> 6.6666667 | H10: =IF(G10="","",IF(AND(G10<=10,G10>6),"MD",IF(AND(G10<=6,G10>2),"D",IF(AND(G10<=2,G10>0),"M",IF(G10=0,"B"))))) -> MD | I10: 3 | J10: =IF(I10=4,"EC",IF(I10=3,"EF",IF(I10=2,"EO",IF(I10=1,"EE","")))) -> EF | K10: =IF(I10="","",G10*I10) -> 20 | L10: =IF(K10="","",IF(K10>=24,"MA",IF(AND(K10<24,K10>8),"A",IF(AND(K10<=8,K10>4),"M",IF(AND(K10<=4,K10>=0),"B"))))) -> A | M10: 25 | N10: =IF(M10="","",IF(M10=100,"M",IF(M10=60,"MG",IF(M10=25,"G",IF(M10=10,"L",""))))) -> G | O10: =IF(M10="","",ROUND(M10*K10,0)) -> 500 | P10: =IF(O10="","",IF(O10="","",IF(AND(O10<=4000,O10>500),"I",IF(AND(O10<=500,O10>120),"II",IF(AND(O10<=120,O10>20),"III",IF(O10<=20,"IV")))))) -> II | Q10: =IF(P10="","",IF(P10="I","Situación Crítica. Corrección urgente.",IF(P10="II","Corregir y adoptar medidas de control.",IF(P10="III","Mejorar si es posible. Sería conveniente justificar la intervención y su rentabilidad.",IF(P10="IV","No intervenir, salvo que un análisis más preciso lo justifique."))))) -> Corregir y adoptar medidas de control. | R10: =IF(M10=10,"Pequeñas lesiones que no requieren hospitalización.",IF(M10=25,"Lesiones con incapacidad laboral transitoria (I. L. T.).",IF(M10=60,"Lesiones graves que pueden ser irreparables.",IF(M10=100,"1 muerto o más.")))) -> Lesiones con incapacidad laboral transitoria (I. L. T.). | S10: Si
